2025-02-07 16:08:09,631 - ERROR - Error in the execution of the main program:: 'filepath'
2025-02-07 16:08:09,632 - ERROR - Traceback: Traceback (most recent call last):
  File "/srv/hemi01-j01/ALPSS/src/alpss/alpss_main.py", line 42, in alpss_main
    sdf_out = spall_doi_finder(**inputs)
  File "/srv/hemi01-j01/ALPSS/src/alpss/spall_doi_finder.py", line 18, in spall_doi_finder
    fname = inputs["filepath"]
KeyError: 'filepath'

2025-02-07 16:08:09,632 - ERROR - Error in the fallback visualization of the voltage signal: 'filepath'
2025-02-07 16:08:09,633 - ERROR - Traceback: Traceback (most recent call last):
  File "/srv/hemi01-j01/ALPSS/src/alpss/alpss_main.py", line 42, in alpss_main
    sdf_out = spall_doi_finder(**inputs)
  File "/srv/hemi01-j01/ALPSS/src/alpss/spall_doi_finder.py", line 18, in spall_doi_finder
    fname = inputs["filepath"]
KeyError: 'filepath'

During handling of the above exception, another exception occurred:

Traceback (most recent call last):
  File "/srv/hemi01-j01/ALPSS/src/alpss/alpss_main.py", line 114, in alpss_main
    plot_voltage(**inputs)
  File "/srv/hemi01-j01/ALPSS/src/alpss/plotting.py", line 423, in plot_voltage
    inputs["filepath"],
KeyError: 'filepath'

2025-02-27 09:17:40,441 - ERROR - Error in the execution of the main program:: 'filepath'
2025-02-27 09:17:40,442 - ERROR - Traceback: Traceback (most recent call last):
  File "/srv/hemi01-j01/ALPSS/src/alpss/alpss_main.py", line 42, in alpss_main
    sdf_out = spall_doi_finder(**inputs)
  File "/srv/hemi01-j01/ALPSS/src/alpss/spall_doi_finder.py", line 18, in spall_doi_finder
    fname = inputs["filepath"]
KeyError: 'filepath'

2025-02-27 09:17:40,442 - ERROR - Error in the fallback visualization of the voltage signal: 'filepath'
2025-02-27 09:17:40,443 - ERROR - Traceback: Traceback (most recent call last):
  File "/srv/hemi01-j01/ALPSS/src/alpss/alpss_main.py", line 42, in alpss_main
    sdf_out = spall_doi_finder(**inputs)
  File "/srv/hemi01-j01/ALPSS/src/alpss/spall_doi_finder.py", line 18, in spall_doi_finder
    fname = inputs["filepath"]
KeyError: 'filepath'

During handling of the above exception, another exception occurred:

Traceback (most recent call last):
  File "/srv/hemi01-j01/ALPSS/src/alpss/alpss_main.py", line 114, in alpss_main
    plot_voltage(**inputs)
  File "/srv/hemi01-j01/ALPSS/src/alpss/plotting.py", line 423, in plot_voltage
    inputs["filepath"],
KeyError: 'filepath'

2025-02-27 09:47:57,674 - ERROR - Error in the execution of the main program:: unsupported operand type(s) for /: 'int' and 'str'
2025-02-27 09:47:57,675 - ERROR - Traceback: Traceback (most recent call last):
  File "/srv/hemi01-j01/ALPSS/src/alpss/alpss_main.py", line 42, in alpss_main
    sdf_out = spall_doi_finder(**inputs)
  File "/srv/hemi01-j01/ALPSS/src/alpss/spall_doi_finder.py", line 11, in spall_doi_finder
    t_step = 1 / inputs["sample_rate"]
TypeError: unsupported operand type(s) for /: 'int' and 'str'

2025-02-27 09:47:57,675 - ERROR - Error in the fallback visualization of the voltage signal: unsupported operand type(s) for /: 'int' and 'str'
2025-02-27 09:47:57,675 - ERROR - Traceback: Traceback (most recent call last):
  File "/srv/hemi01-j01/ALPSS/src/alpss/alpss_main.py", line 42, in alpss_main
    sdf_out = spall_doi_finder(**inputs)
  File "/srv/hemi01-j01/ALPSS/src/alpss/spall_doi_finder.py", line 11, in spall_doi_finder
    t_step = 1 / inputs["sample_rate"]
TypeError: unsupported operand type(s) for /: 'int' and 'str'

During handling of the above exception, another exception occurred:

Traceback (most recent call last):
  File "/srv/hemi01-j01/ALPSS/src/alpss/alpss_main.py", line 114, in alpss_main
    plot_voltage(**inputs)
  File "/srv/hemi01-j01/ALPSS/src/alpss/plotting.py", line 415, in plot_voltage
    t_step = 1 / inputs["sample_rate"]
TypeError: unsupported operand type(s) for /: 'int' and 'str'

2025-02-27 09:50:24,942 - ERROR - Error in the execution of the main program:: unsupported operand type(s) for /: 'int' and 'str'
2025-02-27 09:50:24,942 - ERROR - Traceback: Traceback (most recent call last):
  File "/srv/hemi01-j01/ALPSS/src/alpss/alpss_main.py", line 42, in alpss_main
    sdf_out = spall_doi_finder(**inputs)
  File "/srv/hemi01-j01/ALPSS/src/alpss/spall_doi_finder.py", line 11, in spall_doi_finder
    t_step = 1 / inputs["sample_rate"]
TypeError: unsupported operand type(s) for /: 'int' and 'str'

2025-02-27 09:50:24,942 - ERROR - Error in the fallback visualization of the voltage signal: unsupported operand type(s) for /: 'int' and 'str'
2025-02-27 09:50:24,943 - ERROR - Traceback: Traceback (most recent call last):
  File "/srv/hemi01-j01/ALPSS/src/alpss/alpss_main.py", line 42, in alpss_main
    sdf_out = spall_doi_finder(**inputs)
  File "/srv/hemi01-j01/ALPSS/src/alpss/spall_doi_finder.py", line 11, in spall_doi_finder
    t_step = 1 / inputs["sample_rate"]
TypeError: unsupported operand type(s) for /: 'int' and 'str'

During handling of the above exception, another exception occurred:

Traceback (most recent call last):
  File "/srv/hemi01-j01/ALPSS/src/alpss/alpss_main.py", line 114, in alpss_main
    plot_voltage(**inputs)
  File "/srv/hemi01-j01/ALPSS/src/alpss/plotting.py", line 415, in plot_voltage
    t_step = 1 / inputs["sample_rate"]
TypeError: unsupported operand type(s) for /: 'int' and 'str'

2025-02-27 09:55:15,191 - ERROR - Error in the execution of the main program:: [Errno 2] No such file or directory: 'example_file.csv'
2025-02-27 09:55:15,249 - ERROR - Traceback: Traceback (most recent call last):
  File "/srv/hemi01-j01/ALPSS/src/alpss/alpss_main.py", line 42, in alpss_main
    sdf_out = spall_doi_finder(**inputs)
  File "/srv/hemi01-j01/ALPSS/src/alpss/spall_doi_finder.py", line 19, in spall_doi_finder
    data = pd.read_csv(fname, skiprows=int(rows_to_skip), nrows=int(nrows))
  File "/srv/hemi01-j01/anaconda3/envs/default/lib/python3.9/site-packages/pandas/io/parsers/readers.py", line 1026, in read_csv
    return _read(filepath_or_buffer, kwds)
  File "/srv/hemi01-j01/anaconda3/envs/default/lib/python3.9/site-packages/pandas/io/parsers/readers.py", line 620, in _read
    parser = TextFileReader(filepath_or_buffer, **kwds)
  File "/srv/hemi01-j01/anaconda3/envs/default/lib/python3.9/site-packages/pandas/io/parsers/readers.py", line 1620, in __init__
    self._engine = self._make_engine(f, self.engine)
  File "/srv/hemi01-j01/anaconda3/envs/default/lib/python3.9/site-packages/pandas/io/parsers/readers.py", line 1880, in _make_engine
    self.handles = get_handle(
  File "/srv/hemi01-j01/anaconda3/envs/default/lib/python3.9/site-packages/pandas/io/common.py", line 873, in get_handle
    handle = open(
FileNotFoundError: [Errno 2] No such file or directory: 'example_file.csv'

2025-02-27 09:55:15,268 - ERROR - Error in the fallback visualization of the voltage signal: [Errno 2] No such file or directory: 'example_file.csv'
2025-02-27 09:55:15,269 - ERROR - Traceback: Traceback (most recent call last):
  File "/srv/hemi01-j01/ALPSS/src/alpss/alpss_main.py", line 42, in alpss_main
    sdf_out = spall_doi_finder(**inputs)
  File "/srv/hemi01-j01/ALPSS/src/alpss/spall_doi_finder.py", line 19, in spall_doi_finder
    data = pd.read_csv(fname, skiprows=int(rows_to_skip), nrows=int(nrows))
  File "/srv/hemi01-j01/anaconda3/envs/default/lib/python3.9/site-packages/pandas/io/parsers/readers.py", line 1026, in read_csv
    return _read(filepath_or_buffer, kwds)
  File "/srv/hemi01-j01/anaconda3/envs/default/lib/python3.9/site-packages/pandas/io/parsers/readers.py", line 620, in _read
    parser = TextFileReader(filepath_or_buffer, **kwds)
  File "/srv/hemi01-j01/anaconda3/envs/default/lib/python3.9/site-packages/pandas/io/parsers/readers.py", line 1620, in __init__
    self._engine = self._make_engine(f, self.engine)
  File "/srv/hemi01-j01/anaconda3/envs/default/lib/python3.9/site-packages/pandas/io/parsers/readers.py", line 1880, in _make_engine
    self.handles = get_handle(
  File "/srv/hemi01-j01/anaconda3/envs/default/lib/python3.9/site-packages/pandas/io/common.py", line 873, in get_handle
    handle = open(
FileNotFoundError: [Errno 2] No such file or directory: 'example_file.csv'

During handling of the above exception, another exception occurred:

Traceback (most recent call last):
  File "/srv/hemi01-j01/ALPSS/src/alpss/alpss_main.py", line 114, in alpss_main
    plot_voltage(**inputs)
  File "/srv/hemi01-j01/ALPSS/src/alpss/plotting.py", line 422, in plot_voltage
    data = pd.read_csv(
  File "/srv/hemi01-j01/anaconda3/envs/default/lib/python3.9/site-packages/pandas/io/parsers/readers.py", line 1026, in read_csv
    return _read(filepath_or_buffer, kwds)
  File "/srv/hemi01-j01/anaconda3/envs/default/lib/python3.9/site-packages/pandas/io/parsers/readers.py", line 620, in _read
    parser = TextFileReader(filepath_or_buffer, **kwds)
  File "/srv/hemi01-j01/anaconda3/envs/default/lib/python3.9/site-packages/pandas/io/parsers/readers.py", line 1620, in __init__
    self._engine = self._make_engine(f, self.engine)
  File "/srv/hemi01-j01/anaconda3/envs/default/lib/python3.9/site-packages/pandas/io/parsers/readers.py", line 1880, in _make_engine
    self.handles = get_handle(
  File "/srv/hemi01-j01/anaconda3/envs/default/lib/python3.9/site-packages/pandas/io/common.py", line 873, in get_handle
    handle = open(
FileNotFoundError: [Errno 2] No such file or directory: 'example_file.csv'

