2025-02-27 09:20:54,063 - ERROR - Error in the execution of the main program:: 'filepath'
2025-02-27 09:20:54,063 - ERROR - Traceback: Traceback (most recent call last):
  File "/srv/hemi01-j01/ALPSS/src/alpss/alpss_main.py", line 42, in alpss_main
    sdf_out = spall_doi_finder(**inputs)
  File "/srv/hemi01-j01/ALPSS/src/alpss/spall_doi_finder.py", line 18, in spall_doi_finder
    fname = inputs["filepath"]
KeyError: 'filepath'

2025-02-27 09:20:54,064 - ERROR - Error in the fallback visualization of the voltage signal: 'filepath'
2025-02-27 09:20:54,064 - ERROR - Traceback: Traceback (most recent call last):
  File "/srv/hemi01-j01/ALPSS/src/alpss/alpss_main.py", line 42, in alpss_main
    sdf_out = spall_doi_finder(**inputs)
  File "/srv/hemi01-j01/ALPSS/src/alpss/spall_doi_finder.py", line 18, in spall_doi_finder
    fname = inputs["filepath"]
KeyError: 'filepath'

During handling of the above exception, another exception occurred:

Traceback (most recent call last):
  File "/srv/hemi01-j01/ALPSS/src/alpss/alpss_main.py", line 114, in alpss_main
    plot_voltage(**inputs)
  File "/srv/hemi01-j01/ALPSS/src/alpss/plotting.py", line 423, in plot_voltage
    inputs["filepath"],
KeyError: 'filepath'

